E.
======================================================================
ERROR: test (__main__.Test)
----------------------------------------------------------------------
Traceback (most recent call last):
  File "D:\g\fhopecc\cache.py", line 30, in wrapper
    return pd.read_pickle(p)
  File "C:\python\lib\site-packages\pandas\io\pickle.py", line 187, in read_pickle
    with get_handle(
  File "C:\python\lib\site-packages\pandas\io\common.py", line 798, in get_handle
    handle = open(handle, ioargs.mode)
FileNotFoundError: [Errno 2] No such file or directory: 'C:\\Users\\LGZHAN~1\\AppData\\Local\\Temp\\cache\\fbb78f433b0e2b3e7337e71b3113987c'

During handling of the above exception, another exception occurred:

Traceback (most recent call last):
  File "d:\g\stock\test_tifrs_schema.py", line 12, in test
    p = Account('年度')
  File "D:\g\stock\tifrs_schema.py", line 51, in __init__
    df = 科目表(recache)
  File "D:\g\fhopecc\cache.py", line 32, in wrapper
    df = func(*args, **kargs)
TypeError: 科目表() takes 0 positional arguments but 1 was given

----------------------------------------------------------------------
Ran 2 tests in 1.293s

FAILED (errors=1)
